Workbook

Sheet Cadastro
B1: CADASTRO DA EMPRESA
B2: MODELO DE DEMONSTRATIVOS CONTÁBEIS - Y7 SERVICE
B4: DATA | C4: São Paulo, 02 de Janeiro de 2024
B5: ANO | C5: 2025
B6: NOME | C6: [RAZÃO SOCIAL DA EMPRESA]
B7: CNPJ | C7: 00.000.000/0001-00
B8: CAPITAL SOCIAL | C8: 100000
B9: SÓCIO | C9: [NOME DO SÓCIO ADMINISTRADOR]
B10: QUALIFICAÇÃO | C10: Sócio Administrador
B11: CPF SÓCIO | C11: CPF/MF: 000.000.000-00
B12: CONTADOR | C12: NILSON / RESPONSÁVEL TÉCNICO
B13: CRC | C13: CRC/SP
B14: CPF CONTADOR | C14: CPF/MF: 000.000.000-00
B15: BALANÇO | C15: Encerrado em 31 de Dezembro de 2025 | Valores em R$
B16: DRE | C16: Demonstrativo de Resultado Encerrado em 31/12/2023
B17: FATURAMENTO | C17: Declaração de Faturamento 12 Meses - 2023
B21: total do ativo | C21: ='BP Ativo'!D39
B22: total do passivo | C22: ='BP Passivo'!D33
B23: saldo | C23: =C21-C22

Sheet BP Ativo
B1: Balanço Patrimonial — ATIVO | F1: 17910162
B2: =Cadastro!C15
B3: [EMPRESA AUDITADA] — CNPJ/MF 00.000.000/0001-00
B4: 1 — ATIVO
B5: CÓDIGO | C5: DESCRIÇÃO DA CONTA | D5: 2025 (R$) | E5: 2024 (R$)
B6: 1.1 | C6: ATIVO CIRCULANTE | D6: =D7+D11+D17+D20 | E6: =E7+E11+E17+E20
B7: 1.1.1 | C7: DISPONÍVEL | D7: =SUM(D8:D10) | E7: =SUM(E8:E10)
B8: 1.1.1.001 | C8: Caixa | D8: =0.0224899998899222*Faturamento!D19 | E8: =0.015889057417982*'BP Ativo'!$F$1
B9: 1.1.1.002 | C9: Bancos c/ Movimento | D9: =0.0567759999171238*Faturamento!D19 | E9: =0.0196453305641121*'BP Ativo'!$F$1
B10: 1.1.1.003 | C10: Bancos c/ Aplicação | D10: =0.0511600001583176*Faturamento!D19 | E10: =0.01004610407806*'BP Ativo'!$F$1
B11: 1.1.2 | C11: CRÉDITOS | D11: =SUM(D12:D16) | E11: =SUM(E12:E16)
B12: 1.1.2.001 | C12: Duplicatas a Receber (Clientes) | D12: =0.441862999754904*Faturamento!D19 | E12: =0.298860999963549*'BP Ativo'!$F$1
B13: (-)1.1.2.002 | C13: (-) Duplicatas Descontadas | D13: 0 | E13: =-0.00428491102664156*'BP Ativo'!$F$1
B14: 1.1.2.003 | C14: Adiantamento a Fornecedores | D14: 0 | E14: =0.0148093189900459*'BP Ativo'!$F$1
B15: 1.1.2.005 | C15: Imposto a Recuperar | D15: 0 | E15: =0.0219786059610623*'BP Ativo'!$F$1
B16: 1.1.2.006 | C16: Clientes Diversos | D16: 0 | E16: =0.0610112459703986*'BP Ativo'!$F$1
B17: 1.1.3 | C17: ESTOQUES | D17: =SUM(D18:D19) | E17: =SUM(E18:E19)
B18: 1.1.3.001 | C18: Mercadorias | D18: =0.00488770943234802*Faturamento!D19 | E18: 0
B19: 1.1.3.002 | C19: Material de Uso e Consumo | D19: =0.00128947404759145*Faturamento!D19 | E19: =0.00291232097380516*'BP Ativo'!$F$1
B20: 1.1.4 | C20: DESPESAS DO EXERCÍCIO SEGUINTE | D20: =SUM(D21:D22) | E20: =SUM(E21:E22)
B21: 1.1.4.001 | C21: Prêmios de Seguros a Apropriar | D21: 0 | E21: =0.00570080777913238*'BP Ativo'!$F$1
B22: 1.1.4.002 | C22: Juros Passivos a Apropriar | D22: 0 | E22: =0.000920073204140252*'BP Ativo'!$F$1
B23: 1.2 | C23: NÃO CIRCULANTE | D23: =D24+D28+D31+D37 | E23: =E24+E28+E31+E37
B24: 1.2.1 | C24: REALIZÁVEL A LONGO PRAZO | D24: =SUM(D25:D27) | E24: =SUM(E25:E27)
B25: 1.2.1.001 | C25: Clientes - LP | D25: =0.0700799999943277*Faturamento!D19 | E25: 0
B26: 1.2.1.002 | C26: Investimentos Temporários LP | D26: =0.018947853806805*Faturamento!D19 | E26: =0.00293541624248359*'BP Ativo'!$F$1
B27: 1.2.1.003 | C27: Clientes Diversos LP | D27: 0 | E27: =0.00121654512016596*'BP Ativo'!$F$1
B28: 1.2.2 | C28: INVESTIMENTOS | D28: =SUM(D29:D30) | E28: =SUM(E29:E30)
B29: 1.2.2.001 | C29: Participações em Outras Empresas | D29: 0 | E29: 0
B30: 1.2.2.002 | C30: Imóveis para Revenda | D30: 0 | E30: 0
B31: 1.2.3 | C31: IMOBILIZADO | D31: =SUM(D32:D36) | E31: =SUM(E32:E36)
B32: 1.2.3.001 | C32: Máquinas | D32: 0 | E32: =0.0286713863504254*'BP Ativo'!$F$1
B33: 1.2.3.002 | C33: Veículos | D33: =0.097100000173967*Faturamento!D19 | E33: =0.0284714345001857*'BP Ativo'!$F$1
B34: 1.2.3.003 | C34: Equipamentos de Informática | D34: 0 | E34: =0.000764744066229642*'BP Ativo'!$F$1
B35: 1.2.3.004 | C35: Instalações | D35: 0 | E35: =0.0111445570214096*'BP Ativo'!$F$1
B36: (-)1.2.3.005 | C36: (-) Depreciação Acumulada | D36: =-0.00678020184141549*Faturamento!D19 | E36: =-0.00735626629750417*'BP Ativo'!$F$1
B37: 1.2.4 | C37: DIFERIDO | D37: =SUM(D38:D38) | E37: =SUM(E38:E38)
B38: 1.2.4.001 | C38: Despesas Pré-Operacionais | D38: 0 | E38: =0.0288300761503169*'BP Ativo'!$F$1
C39: TOTAL DO ATIVO | D39: =D6+D23 | E39: =E6+E23
B41: NILSON / CONTADOR RESPONSÁVEL | D41: [SÓCIO ADMINISTRADOR]
...

Sheet BP Passivo
B1: Balanço Patrimonial — PASSIVO | F1: 17910162
B2: Encerrado em 31 de Dezembro de 2025 | Valores em R$
B3: [EMPRESA AUDITADA] — CNPJ/MF 00.000.000/0001-00
B5: 2 — PASSIVO
B6: CÓDIGO | C6: DESCRIÇÃO DA CONTA | D6: 2025 (R$) | E6: 2024 (R$)
B7: 2.1 | C7: PASSIVO CIRCULANTE | D7: =D8 | E7: =E8
B8: 2.1.1 | C8: OBRIGAÇÕES | D8: =SUM(D9:D13) | E8: =SUM(E9:E13)
B9: 2.1.1.001 | C9: Fornecedores | D9: 0 | E9: =0.00833211398366006*'BP Passivo'!$F$1
B10: 2.1.1.002 | C10: Obrigações Fiscais | D10: =0.0299999997720956*Faturamento!D19 | E10: =0.0713000000053042*'BP Passivo'!$F$1
B11: 2.1.1.003 | C11: Imposto de Renda a Pagar | D11: =0.022097327678201*Faturamento!D19 | E11: 0
B12: 2.1.1.004 | C12: Obrigações Sociais e Trabalhistas | D12: =0.00598469288119272*Faturamento!D19 | E12: =0.00519569397414463*'BP Passivo'!$F$1
B13: 2.1.1.005 | C13: Outras Contas a Pagar | D13: =0.00112086124732951*Faturamento!D19 | E13: =0.00411720455781364*'BP Passivo'!$F$1
B14: 2.2 | C14: NÃO CIRCULANTE | D14: =D15 | E14: =E15
B15: 2.2.1 | C15: OBRIGAÇÕES | D15: =SUM(D16:D18) | E15: =SUM(E16:E18)
B16: 2.2.1.001 | C16: Fornecedores a Pagar LP | D16: 0 | E16: =0.0356406382782074*'BP Passivo'!$F$1
B17: 2.2.1.002 | C17: Empréstimos Bancários | D17: 0 | E17: 0
B18: 2.2.1.003 | C18: Outras Contas a Pagar LP | D18: 0 | E18: =0.00392047043393971*'BP Passivo'!$F$1
B19: 2.3 | C19: RESULTADOS DE EXERCÍCIOS FUTUROS | D19: =SUM(D20:D21) | E19: =SUM(E20:E21)
B20: 2.3.001 | C20: Aluguéis Ativos a Vencer | D20: 0 | E20: =0.000103293315576598*'BP Passivo'!$F$1
B21: 2.3.002 | C21: Outras Receitas a Vencer | D21: 0 | E21: =0.00347400489850961*'BP Passivo'!$F$1
B22: 2.4 | C22: PATRIMÔNIO LÍQUIDO | D22: =D23+D26+D28+D31 | E22: =E23+E26+E28+E31
B23: 2.4.1 | C23: CAPITAL SOCIAL | D23: =SUM(D24:D25) | E23: =SUM(E24:E25)
B24: 2.4.1.001 | C24: Capital | D24: =Cadastro!C8 | E24: 200000
B25: 2.4.1.002 | C25: (-) Capital a Realizar | D25: 0 | E25: 0
B26: 2.4.2 | C26: RESERVAS DE LUCROS | D26: =SUM(D27:D27) | E26: =SUM(E27:E27)
B27: 2.4.2.001 | C27: Reserva Legal | D27: =Faturamento!D19*3.81% | E27: 791076.69
B28: 2.4.3 | C28: LUCROS OU PREJUÍZOS ACUMULADOS | D28: =SUM(D29:D30) | E28: =SUM(E29:E30)
B29: 2.4.3.001 | C29: Lucros Acumulados | D29: 5765566.2 | E29: 0
B30: 2.4.3.002 | C30: (-) Prejuízos Acumulados | D30: 0 | E30: 0
B31: 2.4.4 | C31: LUCRO DO PERÍODO | D31: =SUM(D32:D32) | E31: =SUM(E32:E32)
B32: 2.4.4.001 | C32: Lucro do Exercício | D32: =DRE!D25 | E32: 2463883.6
C33: TOTAL DO PASSIVO | D33: =D7+D14+D19+D22 | E33: =E7+E14+E19+E22
B35: NILSON / CONTADOR RESPONSÁVEL | D35: [SÓCIO ADMINISTRADOR]
B36: Contador - CRC/PR 14.660 | D36: Sócio administrador
B37: CPF: 838.177.519-15 | D37: CPF/MF: 387.775.838-09

Sheet DRE
B1: Demonstrativo de Resultado | G1: 17910162
B2: =Cadastro!C16
B3: [EMPRESA AUDITADA] — CNPJ/MF 00.000.000/0001-00
B5: DRE — DEMONSTRATIVO DE RESULTADO DO EXERCÍCIO
B6: CÓDIGO | C6: DESCRIÇÃO DA CONTA | D6: 2025 (R$) | E6: 2024 (R$)
B7: 4 | C7: RECEITA BRUTA DE VENDAS | D7: =D8 | E7: =E8
B8: 4.1 | C8: Receita Bruta de Vendas | D8: =Faturamento!D19 | E8: 17910162
B9: (-)4.1.2 | C9: DEDUÇÕES DA RECEITA BRUTA | D9: =D10 | E9: =E10
B10: 4.1.2.001 | C10: Deduções e Abatimentos de Vendas e Serviços | D10: =0.038289084809646*Faturamento!D19 | E10: =0.0884747281052628*DRE!$G$1
B11: 4.1.1 | C11: RECEITA LÍQUIDA DE VENDAS | D11: =D7-D9 | E11: =E7-E9
B12: (-)4.1.1.007 | C12: CUSTO DAS MERCADORIAS VENDIDAS – CMV | D12: =D13 | E12: =E13
B13: 4.1.1.007a | C13: Custo das Mercadorias Vendidas | D13: =0.715945999953816*Faturamento!D19 | E13: =0.638120697384988*DRE!$G$1
B14: 5 | C14: LUCRO BRUTO | D14: =D11-D12 | E14: =E11-E12
B15: 3.3 | C15: DESPESAS OPERACIONAIS | D15: =D16+D17+D18 | E15: =E16+E17+E18
B16: 3.3.2 | C16: Despesas Administrativas | D16: =0.0219667318661517*Faturamento!D19 | E16: =0.0383318529307428*DRE!$G$1
B17: 3.3.9 | C17: Serviços de Terceiros | D17: =0.0296587250698497*Faturamento!D19 | E17: =0.0671290890651555*DRE!$G$1
B18: 3.3.3 | C18: Despesas Financeiras | D18: =0.00596140307609118*Faturamento!D19 | E18: =0.0104275718759069*DRE!$G$1
B19: 5.1 | C19: LUCRO OPERACIONAL | D19: =D14-D15 | E19: =E14-E15
B20: 5.1a | C20: (-) Despesa com Provisão para CSLL | D20: ='Faturamento Impostos'!F19 | E20: =0.000856202759552393*DRE!$G$1
B21: 5.1.1 | C21: RESULTADO ANTES DO IMPOSTO DE RENDA | D21: =D19-D20 | E21: =E19-E20
B22: 5.1.1.001 | C22: (-) Despesa com Provisão para Imposto de Renda | D22: ='Faturamento Impostos'!G19 | E22: =0.00190267236473913*DRE!$G$1
B23: 5.1.1.002 | C23: RESULTADO ANTES DAS PARTICIPAÇÕES | D23: =D21-D22 | E23: =E21-E22
B24: 5.1.1.002a | C24: (-) Participações | D24: =0.0151742049541289*Faturamento!D19 | E24: =0.0171881523225877*DRE!$G$1
B25: 5.1.1.003 | C25: LUCRO LÍQUIDO DO EXERCÍCIO | D25: =D23-D24 | E25: =E23-E24
B27: NILSON / CONTADOR RESPONSÁVEL | D27: [SÓCIO ADMINISTRADOR]
B28: Contador - CRC/PR 14.660 | D28: Sócio administrador
B29: CPF: 838.177.519-15 | D29: CPF/MF: 387.775.838-09

Sheet Faturamento Projetado
A1: Total desejado | C1: 0
A3: Mês referencia
A5: Mês | B5: Ano | C5: Faturamento Atual (R$) | D5: Participação (%) | E5: Faturamento Projetado (R$)
A6: Janeiro | B6: 2019 | C6: 807500 | D6: =C6/$C$18 | E6: =D6*$C$1
A7: Fevereiro | B7: 2019 | C7: 806250 | D7: =C7/$C$18 | E7: =D7*$C$1
A8: Março | B8: 2019 | C8: 1120000 | D8: =C8/$C$18 | E8: =D8*$C$1
A9: Abril | B9: 2019 | C9: 1081250 | D9: =C9/$C$18 | E9: =D9*$C$1
A10: Maio | B10: 2019 | C10: 991250 | D10: =C10/$C$18 | E10: =D10*$C$1
A11: Junho | B11: 2020 | C11: 835000 | D11: =C11/$C$18 | E11: =D11*$C$1
A12: Julho | B12: 2020 | C12: 981250 | D12: =C12/$C$18 | E12: =D12*$C$1
A13: Agosto | B13: 2020 | C13: 1086250 | D13: =C13/$C$18 | E13: =D13*$C$1
A14: Setembro | B14: 2020 | C14: 1191250 | D14: =C14/$C$18 | E14: =D14*$C$1
A15: Outubro | B15: 2020 | C15: 1012500 | D15: =C15/$C$18 | E15: =D15*$C$1
A16: Novembro | B16: 2020 | C16: 1091250 | D16: =C16/$C$18 | E16: =D16*$C$1
A17: Dezembro | B17: 2020 | C17: 1103750 | D17: =C17/$C$18 | E17: =D17*$C$1
A18: TOTAL ATUAL | C18: =SUM(C6:C17)
A19: TOTAL PROJETADO | D19: =SUM(D6:D17) | E19: =SUM(E6:E17)

Sheet Faturamento
B1: Declaração de Faturamento — 12 Meses
B2: =Cadastro!C17
B3: [EMPRESA AUDITADA] — CNPJ/MF 00.000.000/0001-00
B5: DECLARAÇÃO DE FATURAMENTO 12 MESES
B6: MÊS | D6: FATURAMENTO (R$) | E6: ACUMULADO (R$)
B7: JANEIRO | C7: 2023 | D7: ='Faturamento Projetado'!E6 | E7: =D7
B8: FEVEREIRO | C8: 2023 | D8: ='Faturamento Projetado'!E7 | E8: =E7+D8
B9: MARÇO | C9: 2023 | D9: ='Faturamento Projetado'!E8 | E9: =E8+D9
B10: ABRIL | C10: 2023 | D10: ='Faturamento Projetado'!E9 | E10: =E9+D10
B11: MAIO | C11: 2023 | D11: ='Faturamento Projetado'!E10 | E11: =E10+D11
B12: JUNHO | C12: 2023 | D12: ='Faturamento Projetado'!E11 | E12: =E11+D12
B13: JULHO | C13: 2023 | D13: ='Faturamento Projetado'!E12 | E13: =E12+D13
B14: AGOSTO | C14: 2023 | D14: ='Faturamento Projetado'!E13 | E14: =E13+D14
B15: SETEMBRO | C15: 2023 | D15: ='Faturamento Projetado'!E14 | E15: =E14+D15
B16: OUTUBRO | C16: 2023 | D16: ='Faturamento Projetado'!E15 | E16: =E15+D16
B17: NOVEMBRO | C17: 2023 | D17: ='Faturamento Projetado'!E16 | E17: =E16+D17
B18: DEZEMBRO | C18: 2023 | D18: ='Faturamento Projetado'!E17 | E18: =E17+D18
B19: TOTAL | D19: ='Faturamento Projetado'!E19 | E19: =E18
B21: São Paulo, 02 de Janeiro de 2026
B25: =Cadastro!C12 | E25: =Cadastro!C9
B26: =Cadastro!C13 | E26: =Cadastro!C10
B27: =Cadastro!C14 | E27: =Cadastro!C11

Sheet Faturamento Impostos
B1: Declaração de Faturamento — Impostos
B2: Período: Janeiro a Dezembro 2025 | Valores em R$
B3: [EMPRESA AUDITADA] — CNPJ/MF 00.000.000/0001-00
B5: DECLARAÇÃO DE FATURAMENTO — IMPOSTOS
B6: CÓD. | C6: MÊS | D6: PIS | E6: COFINS | F6: CSLL | G6: IRPJ | H6: FATURAMENTO (R$)
B7: 1 | C7: JANEIRO | D7: 11320.22 | E7: 52247.18 | F7: 18808.98 | G7: 41797.74 | H7: =0.0882026848542626*Faturamento!D19
B8: 2 | C8: FEVEREIRO | D8: 10078.3 | E8: 46515.24 | F8: 16745.49 | G8: 37212.19 | H8: =0.0785261405461744*Faturamento!D19
B9: 3 | C9: MARÇO | D9: 11154.42 | E9: 51481.94 | F9: 18533.5 | G9: 41185.55 | H9: =0.0869108279394289*Faturamento!D19
B10: 4 | C10: ABRIL | D10: 12224.71 | E10: 56421.74 | F10: 20311.83 | G10: 45137.39 | H10: =0.0952500985414363*Faturamento!D19
B11: 5 | C11: MAIO | D11: 10395.53 | E11: 47979.39 | F11: 17272.58 | G11: 38383.51 | H11: =0.0809978884833476*Faturamento!D19
B12: 6 | C12: JUNHO | D12: 11207.59 | E12: 51727.36 | F12: 18621.85 | G12: 41381.89 | H12: =0.0873251399283078*Faturamento!D19
B13: 7 | C13: JULHO | D13: 11332.7 | E13: 52304.77 | F13: 18829.72 | G13: 41843.82 | H13: =0.0882999098893809*Faturamento!D19
B14: 8 | C14: AGOSTO | D14: 8290.83 | E14: 38265.39 | F14: 13775.54 | G14: 30612.31 | H14: =0.0645988998957801*Faturamento!D19
B15: 9 | C15: SETEMBRO | D15: 8279.73 | E15: 38214.15 | F15: 13757.09 | G15: 30571.32 | H15: =0.0645123883938483*Faturamento!D19
B16: 10 | C16: OUTUBRO | D16: 11505.16 | E16: 53100.72 | F16: 19116.26 | G16: 42480.57 | H16: =0.0896436099934292*Faturamento!D19
B17: 11 | C17: NOVEMBRO | D17: 12379.27 | E17: 57135.11 | F17: 20568.64 | G17: 45708.08 | H17: =0.0964543900230458*Faturamento!D19
B18: 12 | C18: DEZEMBRO | D18: 10174.8 | E18: 46960.62 | F18: 16905.82 | G18: 37568.5 | H18: =0.0792780215115582*Faturamento!D19
C19: TOTAL | D19: =SUM(D7:D18) | E19: =SUM(E7:E18) | F19: =SUM(F7:F18) | G19: =SUM(G7:G18) | H19: =SUM(H7:H18)
B21: NILSON / CONTADOR RESPONSÁVEL | E21: [SÓCIO ADMINISTRADOR]
B22: Contador - CRC/PR 14.660 | E22: Sócio administrador
B23: CPF: 838.177.519-15 | E23: CPF/MF: 387.775.838-09
